<?xml version="1.0"?>
<robot name="kuka_kr3" xmlns:xacro="http://www.ros.org/wiki/xacro">
  <!-- Simplified KUKA KR3 URDF with primitive geometry. Dimensions are approximate placeholders. -->

  <!-- Material -->
  <material name="orange"><color rgba="0.9 0.45 0.1 1.0"/></material>
  <material name="dark"><color rgba="0.15 0.15 0.15 1.0"/></material>

  <!-- Base link -->
  <link name="base_link">
    <visual>
      <origin xyz="0 0 0.06" rpy="0 0 0"/>
      <geometry><box size="0.22 0.22 0.12"/></geometry>
      <material name="dark"/>
    </visual>
    <collision>
      <origin xyz="0 0 0.06" rpy="0 0 0"/>
      <geometry><box size="0.22 0.22 0.12"/></geometry>
    </collision>
    <inertial>
      <origin xyz="0 0 0" rpy="0 0 0"/>
      <mass value="8.0"/>
      <inertia ixx="0.02" iyy="0.02" izz="0.02" ixy="0" ixz="0" iyz="0"/>
    </inertial>
  </link>

  <!-- Joint 1: revolute about +Z -->
  <joint name="joint_1" type="revolute">
    <parent link="base_link"/>
    <child link="link_1"/>
    <origin xyz="0 0 0.12" rpy="0 0 0"/>
    <axis xyz="0 0 1"/>
    <limit lower="-3.14" upper="3.14" effort="150" velocity="2.62"/>
  </joint>

  <link name="link_1">
    <visual>
      <origin xyz="0 0 0.09" rpy="0 0 0"/>
      <geometry><cylinder radius="0.07" length="0.18"/></geometry>
      <material name="orange"/>
    </visual>
    <collision>
      <origin xyz="0 0 0.09" rpy="0 0 0"/>
      <geometry><cylinder radius="0.07" length="0.18"/></geometry>
    </collision>
    <inertial>
      <origin xyz="0 0 0.09" rpy="0 0 0"/>
      <mass value="3.0"/>
      <inertia ixx="0.01" iyy="0.01" izz="0.005" ixy="0" ixz="0" iyz="0"/>
    </inertial>
  </link>

  <!-- Joint 2: revolute about +Y -->
  <joint name="joint_2" type="revolute">
    <parent link="link_1"/>
    <child link="link_2"/>
    <origin xyz="0 0 0.18" rpy="0 0 0"/>
    <axis xyz="0 1 0"/>
    <limit lower="-2.27" upper="2.27" effort="120" velocity="2.62"/>
  </joint>

  <link name="link_2">
    <visual>
      <origin xyz="0 0.0 0.11" rpy="0 0 0"/>
      <geometry><box size="0.1 0.08 0.22"/></geometry>
      <material name="orange"/>
    </visual>
    <collision>
      <origin xyz="0 0.0 0.11" rpy="0 0 0"/>
      <geometry><box size="0.1 0.08 0.22"/></geometry>
    </collision>
    <inertial>
      <origin xyz="0 0.0 0.11" rpy="0 0 0"/>
      <mass value="2.5"/>
      <inertia ixx="0.008" iyy="0.008" izz="0.004" ixy="0" ixz="0" iyz="0"/>
    </inertial>
  </link>

  <!-- Joint 3: revolute about +Y -->
  <joint name="joint_3" type="revolute">
    <parent link="link_2"/>
    <child link="link_3"/>
    <origin xyz="0 0 0.22" rpy="0 0 0"/>
    <axis xyz="0 1 0"/>
    <limit lower="-2.44" upper="2.44" effort="100" velocity="2.62"/>
  </joint>

  <link name="link_3">
    <visual>
      <origin xyz="0 0.0 0.07" rpy="0 0 0"/>
      <geometry><box size="0.09 0.07 0.14"/></geometry>
      <material name="orange"/>
    </visual>
    <collision>
      <origin xyz="0 0.0 0.07" rpy="0 0 0"/>
      <geometry><box size="0.09 0.07 0.14"/></geometry>
    </collision>
    <inertial>
      <origin xyz="0 0.0 0.07" rpy="0 0 0"/>
      <mass value="2.0"/>
      <inertia ixx="0.006" iyy="0.006" izz="0.003" ixy="0" ixz="0" iyz="0"/>
    </inertial>
  </link>

  <!-- Joint 4: revolute about +X -->
  <joint name="joint_4" type="revolute">
    <parent link="link_3"/>
    <child link="link_4"/>
    <origin xyz="0 0 0.14" rpy="0 0 0"/>
    <axis xyz="1 0 0"/>
    <limit lower="-3.14" upper="3.14" effort="60" velocity="4.36"/>
  </joint>

  <link name="link_4">
    <visual>
      <origin xyz="0 0 0.05" rpy="0 0 0"/>
      <geometry><cylinder radius="0.045" length="0.10"/></geometry>
      <material name="orange"/>
    </visual>
    <collision>
      <origin xyz="0 0 0.05" rpy="0 0 0"/>
      <geometry><cylinder radius="0.045" length="0.10"/></geometry>
    </collision>
    <inertial>
      <origin xyz="0 0 0.05" rpy="0 0 0"/>
      <mass value="1.2"/>
      <inertia ixx="0.003" iyy="0.003" izz="0.002" ixy="0" ixz="0" iyz="0"/>
    </inertial>
  </link>

  <!-- Joint 5: revolute about +Y -->
  <joint name="joint_5" type="revolute">
    <parent link="link_4"/>
    <child link="link_5"/>
    <origin xyz="0 0 0.10" rpy="0 0 0"/>
    <axis xyz="0 1 0"/>
    <limit lower="-2.09" upper="2.09" effort="50" velocity="4.36"/>
  </joint>

  <link name="link_5">
    <visual>
      <origin xyz="0 0 0.05" rpy="0 0 0"/>
      <geometry><cylinder radius="0.04" length="0.10"/></geometry>
      <material name="orange"/>
    </visual>
    <collision>
      <origin xyz="0 0 0.05" rpy="0 0 0"/>
      <geometry><cylinder radius="0.04" length="0.10"/></geometry>
    </collision>
    <inertial>
      <origin xyz="0 0 0.05" rpy="0 0 0"/>
      <mass value="1.0"/>
      <inertia ixx="0.002" iyy="0.002" izz="0.0015" ixy="0" ixz="0" iyz="0"/>
    </inertial>
  </link>

  <!-- Joint 6: revolute about +X -->
  <joint name="joint_6" type="revolute">
    <parent link="link_5"/>
    <child link="tool0"/>
    <origin xyz="0 0 0.10" rpy="0 0 0"/>
    <axis xyz="1 0 0"/>
    <limit lower="-3.14" upper="3.14" effort="40" velocity="6.28"/>
  </joint>

  <link name="tool0">
    <visual>
      <origin xyz="0 0 0.04" rpy="0 0 0"/>
      <geometry><box size="0.06 0.06 0.08"/></geometry>
      <material name="dark"/>
    </visual>
    <collision>
      <origin xyz="0 0 0.04" rpy="0 0 0"/>
      <geometry><box size="0.06 0.06 0.08"/></geometry>
    </collision>
    <inertial>
      <origin xyz="0 0 0.04" rpy="0 0 0"/>
      <mass value="0.8"/>
      <inertia ixx="0.001" iyy="0.001" izz="0.001" ixy="0" ixz="0" iyz="0"/>
    </inertial>
  </link>

</robot>
